<?xml version="1.0" encoding="utf-8"?>
<sdf version='1.6'>
  <model name='mobile_robot_base'>
    <link name='base_link'>
      <pose frame=''>0 0 0 0 -0 0</pose>
      <inertial>
        <pose frame=''>-0.004391 0 0.038562 0 -0 0</pose>
        <mass>0.165633</mass>
        <inertia>
          <ixx>8.25166e-05</ixx>
          <ixy>6.65224e-11</ixy>
          <ixz>-3.06353e-07</ixz>
          <iyy>0.000148603</iyy>
          <iyz>1.3668e-10</iyz>
          <izz>0.000190467</izz>
        </inertia>
      </inertial>
      <collision name='base_link_collision'>
        <pose frame=''>0 0 0 0 -0 0</pose>
        <geometry>
          <mesh>
            <scale>1 1 1</scale>
            <uri>file://models/mobile_robot_base/meshes/base_link.STL</uri>
          </mesh>
        </geometry>
      </collision>
      <collision name='base_link_fixed_joint_lump__motors_collision_1'>
        <pose frame=''>0.035 0 0.036 1.5708 0 3.14159</pose>
        <geometry>
          <mesh>
            <scale>1 1 1</scale>
            <uri>file://models/mobile_robot_base/meshes/motors.STL</uri>
          </mesh>
        </geometry>
      </collision>
      <visual name='base_link_visual'>
        <pose frame=''>0 0 0 0 -0 0</pose>
        <geometry>
          <mesh>
            <scale>1 1 1</scale>
            <uri>file://models/mobile_robot_base/meshes/base_link.STL</uri>
          </mesh>
        </geometry>
        <material>
          <ambient>0.7 0.7 0.7 1</ambient>
          <diffuse>0.7 0.7 0.7 1</diffuse>
          <specular>0 0 0 0</specular>
          <emissive>0 0 0 1</emissive>
        </material>
      </visual>
      <visual name="visual_april">
        <cast_shadows>false</cast_shadows>
        <pose frame=''>0 0 0.06 0 -0 0</pose>
        <geometry>
          <plane>
            <normal>0 0 1</normal>
            <size>0.1 0.1</size>
          </plane>
        </geometry>
        <material>
          <script>
            <uri>model://mobile_robot_base/materials/scripts</uri>
            <uri>model://mobile_robot_base/materials/textures</uri>
            <name>mobile_robot_base/Image</name>
          </script>
        </material>
      </visual>
      <visual name='base_link_fixed_joint_lump__motors_visual_1'>
        <pose frame=''>0.035 0 0.036 1.5708 0 3.14159</pose>
        <geometry>
          <mesh>
            <scale>1 1 1</scale>
            <uri>file://models/mobile_robot_base/meshes/motors.STL</uri>
          </mesh>
        </geometry>
        <material>
          <ambient>0.4 0.4 0.4 1</ambient>
          <diffuse>0.4 0.4 0.4 1</diffuse>
          <specular>0 0 0 0</specular>
          <emissive>0 0 0 1</emissive>
        </material>
      </visual>
    </link>
    <link name='left_front_wheel'>
      <pose frame=''>0.035 0.0645 0.036 0 -0 0</pose>
      <inertial>
        <pose frame=''>-0 0.01 0 0 -0 0</pose>
        <mass>0.035123</mass>
        <inertia>
          <ixx>1.4693e-05</ixx>
          <ixy>2.2926e-21</ixy>
          <ixz>-3.9204e-22</ixz>
          <iyy>2.7858e-05</iyy>
          <iyz>-7.9353e-25</iyz>
          <izz>1.4693e-05</izz>
        </inertia>
      </inertial>
      <collision name='left_front_wheel_collision'>
        <pose frame=''>0 0 0 0 -0 0</pose>
        <geometry>
          <mesh>
            <scale>1 1 1</scale>
            <uri>file://models/mobile_robot_base/meshes/left_front_wheel.STL</uri>
          </mesh>
        </geometry>
      </collision>
      <visual name='left_front_wheel_visual'>
        <pose frame=''>0 0 0 0 -0 0</pose>
        <geometry>
          <mesh>
            <scale>1 1 1</scale>
            <uri>file://models/mobile_robot_base/meshes/left_front_wheel.STL</uri>
          </mesh>
        </geometry>
        <material>
          <ambient>0.2 0.2 0.2 1</ambient>
          <diffuse>0.2 0.2 0.2 1</diffuse>
          <specular>0 0 0 0</specular>
          <emissive>0 0 0 1</emissive>
        </material>
      </visual>
    </link>
    <joint name='left_front_wheel' type='revolute'>
      <child>left_front_wheel</child>
      <parent>base_link</parent>
      <axis>
        <xyz>0 1 0</xyz>
        <limit>
          <lower>-1e+16</lower>
          <upper>1e+16</upper>
        </limit>
        <dynamics>
          <spring_reference>0</spring_reference>
          <spring_stiffness>0</spring_stiffness>
        </dynamics>
        <use_parent_model_frame>1</use_parent_model_frame>
      </axis>
    </joint>
    <link name='left_rear_wheel'>
      <pose frame=''>-0.05 0.0645 0.036 0 -0 0</pose>
      <inertial>
        <pose frame=''>0 0.01 0 0 -0 0</pose>
        <mass>0.035123</mass>
        <inertia>
          <ixx>1.4693e-05</ixx>
          <ixy>1.1418e-21</ixy>
          <ixz>-3.9204e-22</ixz>
          <iyy>2.7858e-05</iyy>
          <iyz>-1.4418e-24</iyz>
          <izz>1.4693e-05</izz>
        </inertia>
      </inertial>
      <collision name='left_rear_wheel_collision'>
        <pose frame=''>0 0 0 0 -0 0</pose>
        <geometry>
          <mesh>
            <scale>1 1 1</scale>
            <uri>file://models/mobile_robot_base/meshes/left_rear_wheel.STL</uri>
          </mesh>
        </geometry>
      </collision>
      <visual name='left_rear_wheel_visual'>
        <pose frame=''>0 0 0 0 -0 0</pose>
        <geometry>
          <mesh>
            <scale>1 1 1</scale>
            <uri>file://models/mobile_robot_base/meshes/left_rear_wheel.STL</uri>
          </mesh>
        </geometry>
        <material>
          <ambient>0.2 0.2 0.2 1</ambient>
          <diffuse>0.2 0.2 0.2 1</diffuse>
          <specular>0 0 0 0</specular>
          <emissive>0 0 0 1</emissive>
        </material>
      </visual>
    </link>
    <joint name='left_rear_wheel' type='revolute'>
      <child>left_rear_wheel</child>
      <parent>base_link</parent>
      <axis>
        <xyz>0 1 0</xyz>
        <limit>
          <lower>-1e+16</lower>
          <upper>1e+16</upper>
        </limit>
        <dynamics>
          <spring_reference>0</spring_reference>
          <spring_stiffness>0</spring_stiffness>
        </dynamics>
        <use_parent_model_frame>1</use_parent_model_frame>
      </axis>
    </joint>
    <link name='right_front_wheel'>
      <pose frame=''>0.035 -0.0645 0.036 0 -0 0</pose>
      <inertial>
        <pose frame=''>-0 -0.01 0 0 -0 0</pose>
        <mass>0.035123</mass>
        <inertia>
          <ixx>1.4693e-05</ixx>
          <ixy>1.9903e-21</ixy>
          <ixz>-3.9204e-22</ixz>
          <iyy>2.7858e-05</iyy>
          <iyz>-2.4827e-25</iyz>
          <izz>1.4693e-05</izz>
        </inertia>
      </inertial>
      <collision name='right_front_wheel_collision'>
        <pose frame=''>0 0 0 0 -0 0</pose>
        <geometry>
          <mesh>
            <scale>1 1 1</scale>
            <uri>file://models/mobile_robot_base/meshes/right_front_wheel.STL</uri>
          </mesh>
        </geometry>
      </collision>
      <visual name='right_front_wheel_visual'>
        <pose frame=''>0 0 0 0 -0 0</pose>
        <geometry>
          <mesh>
            <scale>1 1 1</scale>
            <uri>file://models/mobile_robot_base/meshes/right_front_wheel.STL</uri>
          </mesh>
        </geometry>
        <material>
          <ambient>0.2 0.2 0.2 1</ambient>
          <diffuse>0.2 0.2 0.2 1</diffuse>
          <specular>0 0 0 0</specular>
          <emissive>0 0 0 1</emissive>
        </material>
      </visual>
    </link>
    <joint name='right_front_wheel' type='revolute'>
      <child>right_front_wheel</child>
      <parent>base_link</parent>
      <axis>
        <xyz>0 1 0</xyz>
        <limit>
          <lower>-1e+16</lower>
          <upper>1e+16</upper>
        </limit>
        <dynamics>
          <spring_reference>0</spring_reference>
          <spring_stiffness>0</spring_stiffness>
        </dynamics>
        <use_parent_model_frame>1</use_parent_model_frame>
      </axis>
    </joint>
    <link name='right_rear_wheel'>
      <pose frame=''>-0.05 -0.0645 0.036 0 -0 0</pose>
      <inertial>
        <pose frame=''>0 -0.01 0 0 -0 0</pose>
        <mass>0.035123</mass>
        <inertia>
          <ixx>1.4693e-05</ixx>
          <ixy>1.1418e-21</ixy>
          <ixz>-3.9204e-22</ixz>
          <iyy>2.7858e-05</iyy>
          <iyz>-1.4418e-24</iyz>
          <izz>1.4693e-05</izz>
        </inertia>
      </inertial>
      <collision name='right_rear_wheel_collision'>
        <pose frame=''>0 0 0 0 -0 0</pose>
        <geometry>
          <mesh>
            <scale>1 1 1</scale>
            <uri>file://models/mobile_robot_base/meshes/right_rear_wheel.STL</uri>
          </mesh>
        </geometry>
      </collision>
      <visual name='right_rear_wheel_visual'>
        <pose frame=''>0 0 0 0 -0 0</pose>
        <geometry>
          <mesh>
            <scale>1 1 1</scale>
            <uri>file://models/mobile_robot_base/meshes/right_rear_wheel.STL</uri>
          </mesh>
        </geometry>
        <material>
          <ambient>0.2 0.2 0.2 1</ambient>
          <diffuse>0.2 0.2 0.2 1</diffuse>
          <specular>0 0 0 0</specular>
          <emissive>0 0 0 1</emissive>
        </material>
      </visual>
    </link>
    <joint name='right_rear_wheel' type='revolute'>
      <child>right_rear_wheel</child>
      <parent>base_link</parent>
      <axis>
        <xyz>0 1 0</xyz>
        <limit>
          <lower>-1e+16</lower>
          <upper>1e+16</upper>
        </limit>
        <dynamics>
          <spring_reference>0</spring_reference>
          <spring_stiffness>0</spring_stiffness>
        </dynamics>
        <use_parent_model_frame>1</use_parent_model_frame>
      </axis>
    </joint>
    <plugin name='skid_steer_drive_controller' filename='libgazebo_ros_skid_steer_drive.so'>
      <updateRate>100.0</updateRate>
      <robotNamespace>/</robotNamespace>
      <leftFrontJoint>left_front_wheel</leftFrontJoint>
      <rightFrontJoint>right_front_wheel</rightFrontJoint>
      <leftRearJoint>left_rear_wheel</leftRearJoint>
      <rightRearJoint>right_rear_wheel</rightRearJoint>
      <wheelSeparation>0.129</wheelSeparation>
      <wheelDiameter>0.07</wheelDiameter>
      <robotBaseFrame>base_link</robotBaseFrame>
      <torque>20</torque>
      <topicName>cmd_vel</topicName>
      <broadcastTF>false</broadcastTF>
    </plugin>
  </model>
</sdf>
